<?xml version="1.0"?>
<robot name="pi_bot" xmlns:xacro="http://ros.org/wiki/xacro">

  <!-- Define hardware constants -->
  <xacro:property name="base_width" value="0.10"/>
  <xacro:property name="base_length" value="0.20"/>
  <xacro:property name="base_height" value="0.15"/>

  <xacro:property name="wheel_radius" value="0.035"/>
  <xacro:property name="wheel_width" value="0.025"/>
  <xacro:property name="wheel_ygap" value="0.0025"/>

  <xacro:property name="lidar_radius" value="0.0325"/>
  <xacro:property name="lidar_height" value="0.035"/>
  <xacro:property name="lidar_xoff" value="-0.030"/>

  <!-- Robot Base -->
  <link name="base_link">
    <visual>
      <geometry>
        <box size="${base_length} ${base_width} ${base_height}"/>
      </geometry>
      <material name="Cyan">
        <color rgba="0 1.0 1.0 1.0"/>
      </material>
    </visual>
  </link>

  <!-- Robot Footprint -->
  <link name="base_footprint"/>

  <joint name="base_joint" type="fixed">
    <parent link="base_link"/>
    <child link="base_footprint"/>
    <origin xyz="0.0 0.0 ${-(wheel_radius+base_height/2)}" rpy="0 0 0"/>
  </joint>

  <!-- Wheels -->
  <xacro:macro name="wheel" params="prefix x_reflect y_reflect">
    <link name="${prefix}_link">
      <visual>
        <origin xyz="0 0 0" rpy="${pi/2} 0 0"/>
        <geometry>
          <cylinder radius="${wheel_radius}" length="${wheel_width}"/>
        </geometry>
        <material name="Gray">
          <color rgba="0.5 0.5 0.5 1.0"/>
        </material>
      </visual>
    </link>

    <joint name="${prefix}_joint" type="continuous">
      <parent link="base_link"/>
      <child link="${prefix}_link"/>
      <origin xyz="${x_reflect*(base_length/2-wheel_radius)} ${y_reflect*(base_width/2+wheel_width/2+wheel_ygap)} ${-base_height/2}" rpy="0 0 0"/>
      <axis xyz="0 1 0"/>
    </joint>
  </xacro:macro>

  <xacro:wheel prefix="drivewhl_l" x_reflect="-1" y_reflect="1" />
  <xacro:wheel prefix="drivewhl_r" x_reflect="-1" y_reflect="-1" />
  <xacro:wheel prefix="steerwhl_l" x_reflect="1" y_reflect="1" />
  <xacro:wheel prefix="steerwhl_r" x_reflect="1" y_reflect="-1" />

  <!-- Lidar -->
  <link name="lidar_link">
    <visual>
      <geometry>
        <cylinder radius="${lidar_radius}" length="${lidar_height}"/>
      </geometry>
      <material name="Red">
        <color rgba="1.0 0.0 0.0 1.0"/>
      </material>
    </visual>
  </link>

  <joint name="lidar_joint" type="fixed">
    <parent link="base_link"/>
    <child link="lidar_link"/>
    <origin xyz="${lidar_xoff} 0.0 ${base_height/2+lidar_height/2}" rpy="0 0 0"/>
  </joint>

</robot>